ValueError: Could not load model distilbert/distilbert-base-uncased-finetuned-sst-2-english with any of the following classes: (<class 'transformers.models.auto.modeling_auto.AutoModelForSequenceClassification'>, <class 'transformers.models.distilbert.modeling_distilbert.DistilBertForSequenceClassification'>). See the original errors: while loading with AutoModelForSequenceClassification, an error is thrown: Traceback (most recent call last): File "D:\IU\computer science project\CS PROJECT\meeting-mood-analyzer\venv\Lib\site-packages\urllib3\response.py", line 779, in _error_catcher yield File "D:\IU\computer science project\CS PROJECT\meeting-mood-analyzer\venv\Lib\site-packages\urllib3\response.py", line 904, in _raw_read data = self._fp_read(amt, read1=read1) if not fp_closed else b"" ^^^^^^^^^^^^^^^^^^^^^^^^^^^^^^^ File "D:\IU\computer science project\CS PROJECT\meeting-mood-analyzer\venv\Lib\site-packages\urllib3\response.py", line 887, in _fp_read return self._fp.read(amt) if amt is not None else self._fp.read() ^^^^^^^^^^^^^^^^^^ File "D:\Lib\http\client.py", line 466, in read s = self.fp.read(amt) ^^^^^^^^^^^^^^^^^ File "D:\Lib\socket.py", line 706, in readinto return self._sock.recv_into(b) ^^^^^^^^^^^^^^^^^^^^^^^ File "D:\Lib\ssl.py", line 1278, in recv_into return self.read(nbytes, buffer) ^^^^^^^^^^^^^^^^^^^^^^^^^ File "D:\Lib\ssl.py", line 1134, in read return self._sslobj.read(len, buffer) ^^^^^^^^^^^^^^^^^^^^^^^^^^^^^^ TimeoutError: The read operation timed out The above exception was the direct cause of the following exception: Traceback (most recent call last): File "D:\IU\computer science project\CS PROJECT\meeting-mood-analyzer\venv\Lib\site-packages\requests\models.py", line 820, in generate yield from self.raw.stream(chunk_size, decode_content=True) File "D:\IU\computer science project\CS PROJECT\meeting-mood-analyzer\venv\Lib\site-packages\urllib3\response.py", line 1091, in stream data = self.read(amt=amt, decode_content=decode_content) ^^^^^^^^^^^^^^^^^^^^^^^^^^^^^^^^^^^^^^^^^^^^^^^^^ File "D:\IU\computer science project\CS PROJECT\meeting-mood-analyzer\venv\Lib\site-packages\urllib3\response.py", line 980, in read data = self._raw_read(amt) ^^^^^^^^^^^^^^^^^^^ File "D:\IU\computer science project\CS PROJECT\meeting-mood-analyzer\venv\Lib\site-packages\urllib3\response.py", line 903, in _raw_read with self._error_catcher(): File "D:\Lib\contextlib.py", line 155, in __exit__ self.gen.throw(typ, value, traceback) File "D:\IU\computer science project\CS PROJECT\meeting-mood-analyzer\venv\Lib\site-packages\urllib3\response.py", line 784, in _error_catcher raise ReadTimeoutError(self._pool, None, "Read timed out.") from e # type: ignore[arg-type] ^^^^^^^^^^^^^^^^^^^^^^^^^^^^^^^^^^^^^^^^^^^^^^^^^^^^^^^^^^^^^^^^^^ urllib3.exceptions.ReadTimeoutError: HTTPSConnectionPool(host='cas-bridge.xethub.hf.co', port=443): Read timed out. During handling of the above exception, another exception occurred: Traceback (most recent call last): File "D:\IU\computer science project\CS PROJECT\meeting-mood-analyzer\venv\Lib\site-packages\huggingface_hub\file_download.py", line 496, in http_get for chunk in r.iter_content(chunk_size=constants.DOWNLOAD_CHUNK_SIZE): File "D:\IU\computer science project\CS PROJECT\meeting-mood-analyzer\venv\Lib\site-packages\requests\models.py", line 826, in generate raise ConnectionError(e) requests.exceptions.ConnectionError: HTTPSConnectionPool(host='cas-bridge.xethub.hf.co', port=443): Read timed out. During handling of the above exception, another exception occurred: Traceback (most recent call last): File "D:\IU\computer science project\CS PROJECT\meeting-mood-analyzer\venv\Lib\site-packages\urllib3\connection.py", line 198, in _new_conn sock = connection.create_connection( ^^^^^^^^^^^^^^^^^^^^^^^^^^^^^ File "D:\IU\computer science project\CS PROJECT\meeting-mood-analyzer\venv\Lib\site-packages\urllib3\util\connection.py", line 60, in create_connection for res in socket.getaddrinfo(host, port, family, socket.SOCK_STREAM): ^^^^^^^^^^^^^^^^^^^^^^^^^^^^^^^^^^^^^^^^^^^^^^^^^^^^^^^^^^ File "D:\Lib\socket.py", line 962, in getaddrinfo for res in _socket.getaddrinfo(host, port, family, type, proto, flags): ^^^^^^^^^^^^^^^^^^^^^^^^^^^^^^^^^^^^^^^^^^^^^^^^^^^^^^^^^^^ socket.gaierror: [Errno 11001] getaddrinfo failed The above exception was the direct cause of the following exception: Traceback (most recent call last): File "D:\IU\computer science project\CS PROJECT\meeting-mood-analyzer\venv\Lib\site-packages\urllib3\connectionpool.py", line 787, in urlopen response = self._make_request( ^^^^^^^^^^^^^^^^^^^ File "D:\IU\computer science project\CS PROJECT\meeting-mood-analyzer\venv\Lib\site-packages\urllib3\connectionpool.py", line 488, in _make_request raise new_e File "D:\IU\computer science project\CS PROJECT\meeting-mood-analyzer\venv\Lib\site-packages\urllib3\connectionpool.py", line 464, in _make_request self._validate_conn(conn) File "D:\IU\computer science project\CS PROJECT\meeting-mood-analyzer\venv\Lib\site-packages\urllib3\connectionpool.py", line 1093, in _validate_conn conn.connect() File "D:\IU\computer science project\CS PROJECT\meeting-mood-analyzer\venv\Lib\site-packages\urllib3\connection.py", line 753, in connect self.sock = sock = self._new_conn() ^^^^^^^^^^^^^^^^ File "D:\IU\computer science project\CS PROJECT\meeting-mood-analyzer\venv\Lib\site-packages\urllib3\connection.py", line 205, in _new_conn raise NameResolutionError(self.host, self, e) from e urllib3.exceptions.NameResolutionError: <urllib3.connection.HTTPSConnection object at 0x000001EBF3C59090>: Failed to resolve 'huggingface.co' ([Errno 11001] getaddrinfo failed) The above exception was the direct cause of the following exception: Traceback (most recent call last): File "D:\IU\computer science project\CS PROJECT\meeting-mood-analyzer\venv\Lib\site-packages\requests\adapters.py", line 667, in send resp = conn.urlopen( ^^^^^^^^^^^^^ File "D:\IU\computer science project\CS PROJECT\meeting-mood-analyzer\venv\Lib\site-packages\urllib3\connectionpool.py", line 841, in urlopen retries = retries.increment( ^^^^^^^^^^^^^^^^^^ File "D:\IU\computer science project\CS PROJECT\meeting-mood-analyzer\venv\Lib\site-packages\urllib3\util\retry.py", line 519, in increment raise MaxRetryError(_pool, url, reason) from reason # type: ignore[arg-type] ^^^^^^^^^^^^^^^^^^^^^^^^^^^^^^^^^^^^^^^^^^^^^^^^^^^ urllib3.exceptions.MaxRetryError: HTTPSConnectionPool(host='huggingface.co', port=443): Max retries exceeded with url: /distilbert/distilbert-base-uncased-finetuned-sst-2-english/resolve/main/model.safetensors (Caused by NameResolutionError("<urllib3.connection.HTTPSConnection object at 0x000001EBF3C59090>: Failed to resolve 'huggingface.co' ([Errno 11001] getaddrinfo failed)")) During handling of the above exception, another exception occurred: Traceback (most recent call last): File "D:\IU\computer science project\CS PROJECT\meeting-mood-analyzer\venv\Lib\site-packages\transformers\pipelines\base.py", line 292, in infer_framework_load_model model = model_class.from_pretrained(model, **kwargs) ^^^^^^^^^^^^^^^^^^^^^^^^^^^^^^^^^^^^^^^^^^^^ File "D:\IU\computer science project\CS PROJECT\meeting-mood-analyzer\venv\Lib\site-packages\transformers\models\auto\auto_factory.py", line 600, in from_pretrained return model_class.from_pretrained( ^^^^^^^^^^^^^^^^^^^^^^^^^^^^ File "D:\IU\computer science project\CS PROJECT\meeting-mood-analyzer\venv\Lib\site-packages\transformers\modeling_utils.py", line 317, in _wrapper return func(*args, **kwargs) ^^^^^^^^^^^^^^^^^^^^^ File "D:\IU\computer science project\CS PROJECT\meeting-mood-analyzer\venv\Lib\site-packages\transformers\modeling_utils.py", line 4918, in from_pretrained checkpoint_files, sharded_metadata = _get_resolved_checkpoint_files( ^^^^^^^^^^^^^^^^^^^^^^^^^^^^^^^ File "D:\IU\computer science project\CS PROJECT\meeting-mood-analyzer\venv\Lib\site-packages\transformers\modeling_utils.py", line 1179, in _get_resolved_checkpoint_files resolved_archive_file = cached_file(pretrained_model_name_or_path, filename, **cached_file_kwargs) ^^^^^^^^^^^^^^^^^^^^^^^^^^^^^^^^^^^^^^^^^^^^^^^^^^^^^^^^^^^^^^^^^^^^^^^^^^ File "D:\IU\computer science project\CS PROJECT\meeting-mood-analyzer\venv\Lib\site-packages\transformers\utils\hub.py", line 321, in cached_file file = cached_files(path_or_repo_id=path_or_repo_id, filenames=[filename], **kwargs) ^^^^^^^^^^^^^^^^^^^^^^^^^^^^^^^^^^^^^^^^^^^^^^^^^^^^^^^^^^^^^^^^^^^^^^^^^^^^^ File "D:\IU\computer science project\CS PROJECT\meeting-mood-analyzer\venv\Lib\site-packages\transformers\utils\hub.py", line 567, in cached_files raise e File "D:\IU\computer science project\CS PROJECT\meeting-mood-analyzer\venv\Lib\site-packages\transformers\utils\hub.py", line 479, in cached_files hf_hub_download( File "D:\IU\computer science project\CS PROJECT\meeting-mood-analyzer\venv\Lib\site-packages\huggingface_hub\utils\_validators.py", line 114, in _inner_fn return fn(*args, **kwargs) ^^^^^^^^^^^^^^^^^^^ File "D:\IU\computer science project\CS PROJECT\meeting-mood-analyzer\venv\Lib\site-packages\huggingface_hub\file_download.py", line 1010, in hf_hub_download return _hf_hub_download_to_cache_dir( ^^^^^^^^^^^^^^^^^^^^^^^^^^^^^^ File "D:\IU\computer science project\CS PROJECT\meeting-mood-analyzer\venv\Lib\site-packages\huggingface_hub\file_download.py", line 1171, in _hf_hub_download_to_cache_dir _download_to_tmp_and_move( File "D:\IU\computer science project\CS PROJECT\meeting-mood-analyzer\venv\Lib\site-packages\huggingface_hub\file_download.py", line 1738, in _download_to_tmp_and_move http_get( File "D:\IU\computer science project\CS PROJECT\meeting-mood-analyzer\venv\Lib\site-packages\huggingface_hub\file_download.py", line 513, in http_get return http_get( ^^^^^^^^^ File "D:\IU\computer science project\CS PROJECT\meeting-mood-analyzer\venv\Lib\site-packages\huggingface_hub\file_download.py", line 426, in http_get r = _request_wrapper( ^^^^^^^^^^^^^^^^^ File "D:\IU\computer science project\CS PROJECT\meeting-mood-analyzer\venv\Lib\site-packages\huggingface_hub\file_download.py", line 309, in _request_wrapper response = http_backoff(method=method, url=url, **params, retry_on_exceptions=(), retry_on_status_codes=(429,)) ^^^^^^^^^^^^^^^^^^^^^^^^^^^^^^^^^^^^^^^^^^^^^^^^^^^^^^^^^^^^^^^^^^^^^^^^^^^^^^^^^^^^^^^^^^^^^^^^^^^^ File "D:\IU\computer science project\CS PROJECT\meeting-mood-analyzer\venv\Lib\site-packages\huggingface_hub\utils\_http.py", line 310, in http_backoff response = session.request(method=method, url=url, **kwargs) ^^^^^^^^^^^^^^^^^^^^^^^^^^^^^^^^^^^^^^^^^^^^^^^^^ File "D:\IU\computer science project\CS PROJECT\meeting-mood-analyzer\venv\Lib\site-packages\requests\sessions.py", line 589, in request resp = self.send(prep, **send_kwargs) ^^^^^^^^^^^^^^^^^^^^^^^^^^^^^^ File "D:\IU\computer science project\CS PROJECT\meeting-mood-analyzer\venv\Lib\site-packages\requests\sessions.py", line 703, in send r = adapter.send(request, **kwargs) ^^^^^^^^^^^^^^^^^^^^^^^^^^^^^^^ File "D:\IU\computer science project\CS PROJECT\meeting-mood-analyzer\venv\Lib\site-packages\huggingface_hub\utils\_http.py", line 96, in send return super().send(request, *args, **kwargs) ^^^^^^^^^^^^^^^^^^^^^^^^^^^^^^^^^^^^^^ File "D:\IU\computer science project\CS PROJECT\meeting-mood-analyzer\venv\Lib\site-packages\requests\adapters.py", line 700, in send raise ConnectionError(e, request=request) requests.exceptions.ConnectionError: (MaxRetryError('HTTPSConnectionPool(host=\'huggingface.co\', port=443): Max retries exceeded with url: /distilbert/distilbert-base-uncased-finetuned-sst-2-english/resolve/main/model.safetensors (Caused by NameResolutionError("<urllib3.connection.HTTPSConnection object at 0x000001EBF3C59090>: Failed to resolve \'huggingface.co\' ([Errno 11001] getaddrinfo failed)"))'), '(Request ID: 39915c0e-35fb-492d-b9da-9e0a93ea9e48)') During handling of the above exception, another exception occurred: Traceback (most recent call last): File "D:\IU\computer science project\CS PROJECT\meeting-mood-analyzer\venv\Lib\site-packages\transformers\pipelines\base.py", line 310, in infer_framework_load_model model = model_class.from_pretrained(model, **fp32_kwargs) ^^^^^^^^^^^^^^^^^^^^^^^^^^^^^^^^^^^^^^^^^^^^^^^^^ File "D:\IU\computer science project\CS PROJECT\meeting-mood-analyzer\venv\Lib\site-packages\transformers\models\auto\auto_factory.py", line 600, in from_pretrained return model_class.from_pretrained( ^^^^^^^^^^^^^^^^^^^^^^^^^^^^ File "D:\IU\computer science project\CS PROJECT\meeting-mood-analyzer\venv\Lib\site-packages\transformers\modeling_utils.py", line 317, in _wrapper return func(*args, **kwargs) ^^^^^^^^^^^^^^^^^^^^^ File "D:\IU\computer science project\CS PROJECT\meeting-mood-analyzer\venv\Lib\site-packages\transformers\modeling_utils.py", line 4918, in from_pretrained checkpoint_files, sharded_metadata = _get_resolved_checkpoint_files( ^^^^^^^^^^^^^^^^^^^^^^^^^^^^^^^ File "D:\IU\computer science project\CS PROJECT\meeting-mood-analyzer\venv\Lib\site-packages\transformers\modeling_utils.py", line 1285, in _get_resolved_checkpoint_files raise OSError( OSError: distilbert/distilbert-base-uncased-finetuned-sst-2-english does not appear to have a file named pytorch_model.bin, model.safetensors, tf_model.h5, model.ckpt or flax_model.msgpack. while loading with DistilBertForSequenceClassification, an error is thrown: Traceback (most recent call last): File "D:\IU\computer science project\CS PROJECT\meeting-mood-analyzer\venv\Lib\site-packages\transformers\pipelines\base.py", line 292, in infer_framework_load_model model = model_class.from_pretrained(model, **kwargs) ^^^^^^^^^^^^^^^^^^^^^^^^^^^^^^^^^^^^^^^^^^^^ File "D:\IU\computer science project\CS PROJECT\meeting-mood-analyzer\venv\Lib\site-packages\transformers\modeling_utils.py", line 317, in _wrapper return func(*args, **kwargs) ^^^^^^^^^^^^^^^^^^^^^ File "D:\IU\computer science project\CS PROJECT\meeting-mood-analyzer\venv\Lib\site-packages\transformers\modeling_utils.py", line 4918, in from_pretrained checkpoint_files, sharded_metadata = _get_resolved_checkpoint_files( ^^^^^^^^^^^^^^^^^^^^^^^^^^^^^^^ File "D:\IU\computer science project\CS PROJECT\meeting-mood-analyzer\venv\Lib\site-packages\transformers\modeling_utils.py", line 1285, in _get_resolved_checkpoint_files raise OSError( OSError: distilbert/distilbert-base-uncased-finetuned-sst-2-english does not appear to have a file named pytorch_model.bin, model.safetensors, tf_model.h5, model.ckpt or flax_model.msgpack. During handling of the above exception, another exception occurred: Traceback (most recent call last): File "D:\IU\computer science project\CS PROJECT\meeting-mood-analyzer\venv\Lib\site-packages\transformers\pipelines\base.py", line 310, in infer_framework_load_model model = model_class.from_pretrained(model, **fp32_kwargs) ^^^^^^^^^^^^^^^^^^^^^^^^^^^^^^^^^^^^^^^^^^^^^^^^^ File "D:\IU\computer science project\CS PROJECT\meeting-mood-analyzer\venv\Lib\site-packages\transformers\modeling_utils.py", line 317, in _wrapper return func(*args, **kwargs) ^^^^^^^^^^^^^^^^^^^^^ File "D:\IU\computer science project\CS PROJECT\meeting-mood-analyzer\venv\Lib\site-packages\transformers\modeling_utils.py", line 4918, in from_pretrained checkpoint_files, sharded_metadata = _get_resolved_checkpoint_files( ^^^^^^^^^^^^^^^^^^^^^^^^^^^^^^^ File "D:\IU\computer science project\CS PROJECT\meeting-mood-analyzer\venv\Lib\site-packages\transformers\modeling_utils.py", line 1285, in _get_resolved_checkpoint_files raise OSError( OSError: distilbert/distilbert-base-uncased-finetuned-sst-2-english does not appear to have a file named pytorch_model.bin, model.safetensors, tf_model.h5, model.ckpt or flax_model.msgpack. File "D:\IU\computer science project\CS PROJECT\meeting-mood-analyzer\venv\Lib\site-packages\streamlit\runtime\scriptrunner\exec_code.py", line 128, in exec_func_with_error_handling result = func() ^^^^^^ File "D:\IU\computer science project\CS PROJECT\meeting-mood-analyzer\venv\Lib\site-packages\streamlit\runtime\scriptrunner\script_runner.py", line 669, in code_to_exec exec(code, module.__dict__) # noqa: S102 ^^^^^^^^^^^^^^^^^^^^^^^^^^^ File "D:\IU\computer science project\CS PROJECT\meeting-mood-analyzer\app.py", line 125, in <module> res = analyze_text(text) ^^^^^^^^^^^^^^^^^^ File "D:\IU\computer science project\CS PROJECT\meeting-mood-analyzer\analyzer_utils.py", line 389, in analyze_text nlp = get_sentiment_pipeline() ^^^^^^^^^^^^^^^^^^^^^^^^ File "D:\IU\computer science project\CS PROJECT\meeting-mood-analyzer\analyzer_utils.py", line 365, in get_sentiment_pipeline _SENTIMENT = pipeline( ^^^^^^^^^ File "D:\IU\computer science project\CS PROJECT\meeting-mood-analyzer\venv\Lib\site-packages\transformers\pipelines\__init__.py", line 1008, in pipeline framework, model = infer_framework_load_model( ^^^^^^^^^^^^^^^^^^^^^^^^^^^ File "D:\IU\computer science project\CS PROJECT\meeting-mood-analyzer\venv\Lib\site-packages\transformers\pipelines\base.py", line 332, in infer_framework_load_model raise ValueError( I get this error when I upload a text file and I want to give a button for start analysing